<mujoco model="biped_tail">
  <compiler angle="radian"/>

  <option timestep="0.01" integrator="RK4"/>

  <default>
    <joint limited="true" armature="1" damping="1"/>
    <geom conaffinity="0" friction="1 0.5 0.5" margin="0.01" density="5" rgba="0.75 0.45 0.65 1"/>
  </default>

  <asset>
    <texture type="skybox" colorspace="auto" name="sky" builtin="gradient" rgb1="1 1 1" rgb2="0 0 0" width="100" height="600"/>
    <texture type="2d" colorspace="auto" name="texplane" builtin="checker" rgb1="0 0 0" rgb2="0.8 0.8 0.8" width="100" height="100"/>
    <material name="MatPlane" texture="texplane" texrepeat="60 60" specular="1" shininess="1" reflectance="0.5"/>
  </asset>

  <worldbody>
    <geom name="floor" size="40 40 40" type="plane" conaffinity="1" material="MatPlane" rgba="0.8 0.9 0.8 1"/>
    <light pos="0 0 1.3" dir="0 0 -1" type="directional" cutoff="100" diffuse="1 1 1" specular="0.1 0.1 0.1"/>
    <body name="torso" pos="0 0 0.751386">
      <joint name="root" type="free" margin="0.01" armature="0" damping="0"/>
      <geom name="torso_geom" size="0.2"/>
      <camera name="track" pos="0 -3 0.3" quat="0.707107 0.707107 0 0" mode="trackcom"/>
      <body name="leg_l">
        <geom name="leg_l_mount_geom" size="0.07 0.06" pos="0 0.06 0" quat="0.707107 0.707107 0 0" type="capsule"/>
        <body name="leg_l_seg1" pos="0 0.12 0">
          <joint name="leg_l_seg1_joint" pos="0 0 0" axis="0 0 1" range="-0.436332 0.436332"/>
          <geom name="leg_l_seg1_geom" size="0.07 0.175" pos="0 0.100376 -0.143352" quat="0.953717 0.300706 0 0" type="capsule"/>
          <body name="leg_l_seg2" pos="0 0.200752 -0.286703">
            <joint name="leg_l_seg2_joint" pos="0 0 0" axis="-1 0 0" range="-0.872665 0.872665"/>
            <geom name="leg_l_seg2_geom" size="0.07 0.175" pos="0 0.0303884 -0.172341" quat="0.996195 0.0871557 0 0" type="capsule"/>
          </body>
        </body>
      </body>
      <body name="leg_r">
        <geom name="leg_r_mount_geom" size="0.07 0.06" pos="0 -0.06 0" quat="0.707107 -0.707107 0 0" type="capsule"/>
        <body name="leg_r_seg1" pos="0 -0.12 0">
          <joint name="leg_r_seg1_joint" pos="0 0 0" axis="0 0 1" range="-0.436332 0.436332"/>
          <geom name="leg_r_seg1_geom" size="0.07 0.175" pos="0 -0.100376 -0.143352" quat="0.953717 -0.300706 0 0" type="capsule"/>
          <body name="leg_r_seg2" pos="0 -0.200752 -0.286703">
            <joint name="leg_r_seg2_joint" pos="0 0 0" axis="1 0 0" range="-0.872665 0.872665"/>
            <geom name="leg_r_seg2_geom" size="0.07 0.175" pos="0 -0.0303884 -0.172341" quat="0.996195 -0.0871557 0 0" type="capsule"/>
          </body>
        </body>
      </body>
      <body name="tail">
        <geom name="tail_mount_geom" size="0.05 0.075" pos="-0.075 0 0" quat="0.707107 0 0.707107 0" type="capsule"/>
        <body name="tail_seg1" pos="-0.15 0 0">
          <joint name="tail_seg1_joint" pos="0 0 0" axis="0 0 1" range="-0.698132 0.698132"/>
          <geom name="tail_seg1_geom" size="0.05 0.175" pos="-0.158604 0 0.0739582" quat="0.5373 0 0.843391 0" type="capsule"/>
          <body name="tail_seg2" pos="-0.317208 0 0.147916">
            <joint name="tail_seg2_joint" pos="0 0 0" axis="0 -1 0" range="-0.698132 0.698132"/>
            <geom name="tail_seg2_geom" size="0.05 0.15" pos="-0.147721 0 0.0260472" quat="0.642788 0 0.766044 0" type="capsule"/>
          </body>
        </body>
      </body>
    </body>
  </worldbody>

  <actuator>
    <general name="leg_l_seg1_motor" joint="leg_l_seg1_joint" ctrllimited="true" ctrlrange="-1 1" gear="180 0 0 0 0 0"/>
    <general name="leg_l_seg2_motor" joint="leg_l_seg2_joint" ctrllimited="true" ctrlrange="-1 1" gear="180 0 0 0 0 0"/>
    <general name="leg_r_seg1_motor" joint="leg_r_seg1_joint" ctrllimited="true" ctrlrange="-1 1" gear="180 0 0 0 0 0"/>
    <general name="leg_r_seg2_motor" joint="leg_r_seg2_joint" ctrllimited="true" ctrlrange="-1 1" gear="180 0 0 0 0 0"/>
    <general name="tail_seg1_motor" joint="tail_seg1_joint" ctrllimited="true" ctrlrange="-1 1" gear="80 0 0 0 0 0"/>
    <general name="tail_seg2_motor" joint="tail_seg2_joint" ctrllimited="true" ctrlrange="-1 1" gear="80 0 0 0 0 0"/>
  </actuator>
</mujoco>
