<mujoco model="spider8">
  <compiler angle="radian"/>

  <option timestep="0.01" integrator="RK4"/>

  <default>
    <joint limited="true" armature="1" damping="1"/>
    <geom conaffinity="0" friction="1 0.5 0.5" margin="0.01" density="5" rgba="0.3 0.3 0.35 1"/>
  </default>

  <asset>
    <texture type="skybox" colorspace="auto" name="sky" builtin="gradient" rgb1="1 1 1" rgb2="0 0 0" width="100" height="600"/>
    <texture type="2d" colorspace="auto" name="texplane" builtin="checker" rgb1="0 0 0" rgb2="0.8 0.8 0.8" width="100" height="100"/>
    <material name="MatPlane" texture="texplane" texrepeat="60 60" specular="1" shininess="1" reflectance="0.5"/>
  </asset>

  <worldbody>
    <geom name="floor" size="40 40 40" type="plane" conaffinity="1" material="MatPlane" rgba="0.8 0.9 0.8 1"/>
    <light pos="0 0 1.3" dir="0 0 -1" type="directional" cutoff="100" diffuse="1 1 1" specular="0.1 0.1 0.1"/>
    <body name="torso" pos="0 0 0.362926">
      <joint name="root" type="free" margin="0.01" armature="0" damping="0"/>
      <geom name="torso_geom" size="0.22"/>
      <camera name="track" pos="0 -3 0.3" quat="0.707107 0.707107 0 0" mode="trackcom"/>
      <body name="leg1">
        <geom name="leg1_mount_geom" size="0.05 0.1" pos="0.092388 0.0382683 0" quat="0.707107 0.270598 -0.653281 0" type="capsule"/>
        <body name="leg1_seg1" pos="0.184776 0.0765367 0">
          <joint name="leg1_seg1_joint" pos="0 0 0" axis="0 0 1" range="-0.610865 0.610865"/>
          <geom name="leg1_seg1_geom" size="0.05 0.15" pos="0.125598 0.0520243 0.0633927" quat="0.5373 0.322752 -0.779192 0" type="capsule"/>
          <body name="leg1_seg2" pos="0.251196 0.104049 0.126785">
            <joint name="leg1_seg2_joint" pos="0 0 0" axis="-0.382683 0.92388 0" range="-0.785398 0.785398"/>
            <geom name="leg1_seg2_geom" size="0.05 0.225" pos="0.103936 0.0430519 -0.194856" quat="0.965926 0.0990458 -0.239118 0" type="capsule"/>
          </body>
        </body>
      </body>
      <body name="leg2">
        <geom name="leg2_mount_geom" size="0.05 0.1" pos="0.0382683 0.092388 0" quat="0.707107 0.653281 -0.270598 0" type="capsule"/>
        <body name="leg2_seg1" pos="0.0765367 0.184776 0">
          <joint name="leg2_seg1_joint" pos="0 0 0" axis="0 0 1" range="-0.610865 0.610865"/>
          <geom name="leg2_seg1_geom" size="0.05 0.15" pos="0.0520243 0.125598 0.0633927" quat="0.5373 0.779192 -0.322752 0" type="capsule"/>
          <body name="leg2_seg2" pos="0.104049 0.251196 0.126785">
            <joint name="leg2_seg2_joint" pos="0 0 0" axis="-0.92388 0.382683 0" range="-0.785398 0.785398"/>
            <geom name="leg2_seg2_geom" size="0.05 0.225" pos="0.0430519 0.103936 -0.194856" quat="0.965926 0.239118 -0.0990458 0" type="capsule"/>
          </body>
        </body>
      </body>
      <body name="leg3">
        <geom name="leg3_mount_geom" size="0.05 0.1" pos="-0.0382683 0.092388 0" quat="0.707107 0.653281 0.270598 0" type="capsule"/>
        <body name="leg3_seg1" pos="-0.0765367 0.184776 0">
          <joint name="leg3_seg1_joint" pos="0 0 0" axis="0 0 1" range="-0.610865 0.610865"/>
          <geom name="leg3_seg1_geom" size="0.05 0.15" pos="-0.0520243 0.125598 0.0633927" quat="0.5373 0.779192 0.322752 0" type="capsule"/>
          <body name="leg3_seg2" pos="-0.104049 0.251196 0.126785">
            <joint name="leg3_seg2_joint" pos="0 0 0" axis="-0.92388 -0.382683 0" range="-0.785398 0.785398"/>
            <geom name="leg3_seg2_geom" size="0.05 0.225" pos="-0.0430519 0.103936 -0.194856" quat="0.965926 0.239118 0.0990458 0" type="capsule"/>
          </body>
        </body>
      </body>
      <body name="leg4">
        <geom name="leg4_mount_geom" size="0.05 0.1" pos="-0.092388 0.0382683 0" quat="0.707107 0.270598 0.653281 0" type="capsule"/>
        <body name="leg4_seg1" pos="-0.184776 0.0765367 0">
          <joint name="leg4_seg1_joint" pos="0 0 0" axis="0 0 1" range="-0.610865 0.610865"/>
          <geom name="leg4_seg1_geom" size="0.05 0.15" pos="-0.125598 0.0520243 0.0633927" quat="0.5373 0.322752 0.779192 0" type="capsule"/>
          <body name="leg4_seg2" pos="-0.251196 0.104049 0.126785">
            <joint name="leg4_seg2_joint" pos="0 0 0" axis="-0.382683 -0.92388 0" range="-0.785398 0.785398"/>
            <geom name="leg4_seg2_geom" size="0.05 0.225" pos="-0.103936 0.0430519 -0.194856" quat="0.965926 0.0990458 0.239118 0" type="capsule"/>
          </body>
        </body>
      </body>
      <body name="leg5">
        <geom name="leg5_mount_geom" size="0.05 0.1" pos="-0.092388 -0.0382683 0" quat="0.707107 -0.270598 0.653281 0" type="capsule"/>
        <body name="leg5_seg1" pos="-0.184776 -0.0765367 0">
          <joint name="leg5_seg1_joint" pos="0 0 0" axis="0 0 1" range="-0.610865 0.610865"/>
          <geom name="leg5_seg1_geom" size="0.05 0.15" pos="-0.125598 -0.0520243 0.0633927" quat="0.5373 -0.322752 0.779192 0" type="capsule"/>
          <body name="leg5_seg2" pos="-0.251196 -0.104049 0.126785">
            <joint name="leg5_seg2_joint" pos="0 0 0" axis="0.382683 -0.92388 0" range="-0.785398 0.785398"/>
            <geom name="leg5_seg2_geom" size="0.05 0.225" pos="-0.103936 -0.0430519 -0.194856" quat="0.965926 -0.0990458 0.239118 0" type="capsule"/>
          </body>
        </body>
      </body>
      <body name="leg6">
        <geom name="leg6_mount_geom" size="0.05 0.1" pos="-0.0382683 -0.092388 0" quat="0.707107 -0.653281 0.270598 0" type="capsule"/>
        <body name="leg6_seg1" pos="-0.0765367 -0.184776 0">
          <joint name="leg6_seg1_joint" pos="0 0 0" axis="0 0 1" range="-0.610865 0.610865"/>
          <geom name="leg6_seg1_geom" size="0.05 0.15" pos="-0.0520243 -0.125598 0.0633927" quat="0.5373 -0.779192 0.322752 0" type="capsule"/>
          <body name="leg6_seg2" pos="-0.104049 -0.251196 0.126785">
            <joint name="leg6_seg2_joint" pos="0 0 0" axis="0.92388 -0.382683 0" range="-0.785398 0.785398"/>
            <geom name="leg6_seg2_geom" size="0.05 0.225" pos="-0.0430519 -0.103936 -0.194856" quat="0.965926 -0.239118 0.0990458 0" type="capsule"/>
          </body>
        </body>
      </body>
      <body name="leg7">
        <geom name="leg7_mount_geom" size="0.05 0.1" pos="0.0382683 -0.092388 0" quat="0.707107 -0.653281 -0.270598 0" type="capsule"/>
        <body name="leg7_seg1" pos="0.0765367 -0.184776 0">
          <joint name="leg7_seg1_joint" pos="0 0 0" axis="0 0 1" range="-0.610865 0.610865"/>
          <geom name="leg7_seg1_geom" size="0.05 0.15" pos="0.0520243 -0.125598 0.0633927" quat="0.5373 -0.779192 -0.322752 0" type="capsule"/>
          <body name="leg7_seg2" pos="0.104049 -0.251196 0.126785">
            <joint name="leg7_seg2_joint" pos="0 0 0" axis="0.92388 0.382683 0" range="-0.785398 0.785398"/>
            <geom name="leg7_seg2_geom" size="0.05 0.225" pos="0.0430519 -0.103936 -0.194856" quat="0.965926 -0.239118 -0.0990458 0" type="capsule"/>
          </body>
        </body>
      </body>
      <body name="leg8">
        <geom name="leg8_mount_geom" size="0.05 0.1" pos="0.092388 -0.0382683 0" quat="0.707107 -0.270598 -0.653281 0" type="capsule"/>
        <body name="leg8_seg1" pos="0.184776 -0.0765367 0">
          <joint name="leg8_seg1_joint" pos="0 0 0" axis="0 0 1" range="-0.610865 0.610865"/>
          <geom name="leg8_seg1_geom" size="0.05 0.15" pos="0.125598 -0.0520243 0.0633927" quat="0.5373 -0.322752 -0.779192 0" type="capsule"/>
          <body name="leg8_seg2" pos="0.251196 -0.104049 0.126785">
            <joint name="leg8_seg2_joint" pos="0 0 0" axis="0.382683 0.92388 0" range="-0.785398 0.785398"/>
            <geom name="leg8_seg2_geom" size="0.05 0.225" pos="0.103936 -0.0430519 -0.194856" quat="0.965926 -0.0990458 -0.239118 0" type="capsule"/>
          </body>
        </body>
      </body>
    </body>
  </worldbody>

  <actuator>
    <general name="leg1_seg1_motor" joint="leg1_seg1_joint" ctrllimited="true" ctrlrange="-1 1" gear="100 0 0 0 0 0"/>
    <general name="leg1_seg2_motor" joint="leg1_seg2_joint" ctrllimited="true" ctrlrange="-1 1" gear="100 0 0 0 0 0"/>
    <general name="leg2_seg1_motor" joint="leg2_seg1_joint" ctrllimited="true" ctrlrange="-1 1" gear="100 0 0 0 0 0"/>
    <general name="leg2_seg2_motor" joint="leg2_seg2_joint" ctrllimited="true" ctrlrange="-1 1" gear="100 0 0 0 0 0"/>
    <general name="leg3_seg1_motor" joint="leg3_seg1_joint" ctrllimited="true" ctrlrange="-1 1" gear="100 0 0 0 0 0"/>
    <general name="leg3_seg2_motor" joint="leg3_seg2_joint" ctrllimited="true" ctrlrange="-1 1" gear="100 0 0 0 0 0"/>
    <general name="leg4_seg1_motor" joint="leg4_seg1_joint" ctrllimited="true" ctrlrange="-1 1" gear="100 0 0 0 0 0"/>
    <general name="leg4_seg2_motor" joint="leg4_seg2_joint" ctrllimited="true" ctrlrange="-1 1" gear="100 0 0 0 0 0"/>
    <general name="leg5_seg1_motor" joint="leg5_seg1_joint" ctrllimited="true" ctrlrange="-1 1" gear="100 0 0 0 0 0"/>
    <general name="leg5_seg2_motor" joint="leg5_seg2_joint" ctrllimited="true" ctrlrange="-1 1" gear="100 0 0 0 0 0"/>
    <general name="leg6_seg1_motor" joint="leg6_seg1_joint" ctrllimited="true" ctrlrange="-1 1" gear="100 0 0 0 0 0"/>
    <general name="leg6_seg2_motor" joint="leg6_seg2_joint" ctrllimited="true" ctrlrange="-1 1" gear="100 0 0 0 0 0"/>
    <general name="leg7_seg1_motor" joint="leg7_seg1_joint" ctrllimited="true" ctrlrange="-1 1" gear="100 0 0 0 0 0"/>
    <general name="leg7_seg2_motor" joint="leg7_seg2_joint" ctrllimited="true" ctrlrange="-1 1" gear="100 0 0 0 0 0"/>
    <general name="leg8_seg1_motor" joint="leg8_seg1_joint" ctrllimited="true" ctrlrange="-1 1" gear="100 0 0 0 0 0"/>
    <general name="leg8_seg2_motor" joint="leg8_seg2_joint" ctrllimited="true" ctrlrange="-1 1" gear="100 0 0 0 0 0"/>
  </actuator>
</mujoco>
